<?xml version='1.0' encoding='UTF-8'?>
<mujoco model="ur3">
  <compiler angle="radian" meshdir="../meshes/visual/"/>

  <asset>
    <mesh name="base" content_type="model/stl" file="base.stl"/>
    <mesh name="shoulder" content_type="model/stl" file="shoulder.stl"/>
    <mesh name="upperarm" content_type="model/stl" file="upperarm.stl"/>
    <mesh name="forearm" content_type="model/stl" file="forearm.stl"/>
    <mesh name="wrist1" content_type="model/stl" file="wrist1.stl"/>
    <mesh name="wrist2" content_type="model/stl" file="wrist2.stl"/>
    <mesh name="wrist3" content_type="model/stl" file="wrist3.stl"/>
  </asset>

  <worldbody>
    <body name="base_link">
      <inertial pos="0 0 0" quat="0.5 0.5 -0.5 0.5" mass="2" diaginertia="0.005625 0.00305317 0.00305317"/>
      <geom type="mesh" rgba="0.7 0.7 0.7 1" mesh="base" contype="1" conaffinity="0"/>
      <body name="shoulder_link" pos="0 0 0.1519">
        <inertial pos="0.000000e+00 0.000000e+00 0.000000e+00" mass="1.690000e+00" diaginertia="7.658552e-03 7.658552e-03 5.247625e-03"/>
        <joint name="shoulder_pan_joint" pos="0 0 0" axis="0 0 1" range="-6.28319 6.28319" actuatorfrcrange="-330 330" armature="3.896782e-01"/>
        <geom type="mesh" rgba="0.7 0.7 0.7 1" mesh="shoulder" contype="1" conaffinity="0"/>
        <body name="upper_arm_link" pos="0 0.1198 0" quat="0.707107 0 0.707107 0">
          <inertial pos="0.000000e+00 0.000000e+00 1.218250e-01" mass="3.110000e+00" diaginertia="2.129389e-02 2.129389e-02 9.241375e-03"/>
          <joint name="shoulder_lift_joint" pos="0 0 0" axis="0 1 0" range="-6.28319 6.28319" actuatorfrcrange="-330 330" armature="3.896782e-01"/>
          <geom type="mesh" rgba="0.7 0.7 0.7 1" mesh="upperarm" contype="1" conaffinity="0"/>
          <body name="forearm_link" pos="0 -0.0925 0.24365">
            <inertial pos="0.000000e+00 0.000000e+00 1.066250e-01" mass="1.610000e+00" diaginertia="6.890423e-03 6.890423e-03 3.936250e-03"/>
            <joint name="elbow_joint" pos="0 0 0" axis="0 1 0" range="-3.14159 3.14159" actuatorfrcrange="-150 150" armature="2.172813e-01"/>
            <geom type="mesh" rgba="0.7 0.7 0.7 1" mesh="forearm" contype="1" conaffinity="0"/>
            <body name="wrist_1_link" pos="0 0 0.21325" quat="0.707107 0 0.707107 0">
              <inertial pos="0.000000e+00 0.000000e+00 0.000000e+00" quat="0.5 0.5 -0.5 0.5" mass="8.000000e-01" diaginertia="2.315229e-03 2.150229e-03 2.092650e-03"/>
              <joint name="wrist_1_joint" pos="0 0 0" axis="0 1 0" range="-6.28319 6.28319" actuatorfrcrange="-54 54" armature="6.151203e-02"/>
              <geom type="mesh" rgba="0.7 0.7 0.7 1" mesh="wrist1" contype="1" conaffinity="0"/>
              <body name="wrist_2_link" pos="0 0.08505 0">
                <inertial pos="0.000000e+00 0.000000e+00 0.000000e+00" quat="0.5 0.5 -0.5 0.5" mass="8.000000e-01" diaginertia="2.315229e-03 2.150229e-03 2.092650e-03"/>
                <joint name="wrist_2_joint" pos="0 0 0" axis="0 0 1" range="-6.28319 6.28319" actuatorfrcrange="-54 54" armature="6.151203e-02"/>
                <geom type="mesh" rgba="0.7 0.7 0.7 1" mesh="wrist2" contype="1" conaffinity="0"/>
                <body name="wrist_3_link" pos="0 0 0.08535">
                  <inertial pos="0.000000e+00 0.000000e+00 0.000000e+00" quat="0.5 0.5 -0.5 0.5" mass="5.000000e-01" diaginertia="1.123979e-03 1.051791e-03 9.835870e-04"/>
                  <joint name="wrist_3_joint" pos="0 0 0" axis="0 1 0" range="-6.28319 6.28319" actuatorfrcrange="-54 54" armature="6.151203e-02"/>
                  <geom type="mesh" rgba="0.7 0.7 0.7 1" mesh="wrist3" contype="1" conaffinity="0"/>
                  <body name="ee_link" pos="0 0.0819 0" quat="0.707107 0 0 0.707107">
                    <geom size="0.005 0.005 0.005" pos="-0.01 0 0" type="box" contype="1" conaffinity="0"/>
                  </body>
                  <body name="tool0" pos="0 0.0819 0" quat="0.707107 -0.707107 0 0"/>
                </body>
              </body>
            </body>
          </body>
        </body>
      </body>
      <body name="base" quat="0 0 0 -1"/>
    </body>
  </worldbody>
<actuator><general name="shoulder_pan_joint_CRA-RI60-70-PRO-S-101" joint="shoulder_pan_joint" gear="101.000000" ctrlrange="-66.000 66.000"/><general name="shoulder_lift_joint_CRA-RI60-70-PRO-S-101" joint="shoulder_lift_joint" gear="101.000000" ctrlrange="-66.000 66.000"/><general name="elbow_joint_CRA-RI60-80-NH-101" joint="elbow_joint" gear="101.000000" ctrlrange="-48.000 48.000"/><general name="wrist_1_joint_CRA-RI40-52-PRO-101" joint="wrist_1_joint" gear="101.000000" ctrlrange="-11.000 11.000"/><general name="wrist_2_joint_CRA-RI40-52-PRO-101" joint="wrist_2_joint" gear="101.000000" ctrlrange="-11.000 11.000"/><general name="wrist_3_joint_CRA-RI40-52-PRO-101" joint="wrist_3_joint" gear="101.000000" ctrlrange="-11.000 11.000"/></actuator></mujoco>
